<?xml version='1.0' encoding='UTF-8'?>
<robot name="pendulum">
  <link name="base_link"/>
  <link name="pendulum_link">
    <inertial>
      <origin xyz="1.6657760534876635e-08 0.01808900658566693 -0.0933199577487272" rpy="0 0 0"/>
      <mass value="0.18269208799931075"/>
      <inertia ixx="0.0023056891285520562" iyy="0.0022904151156667783" izz="1.5412486202460495e-05" ixy="-2.0159756527119397e-11" ixz="-2.291606565873516e-10" iyz="0.00017027812660696617"/>
    </inertial>
    <visual>
      <origin xyz="1.6047283079967634e-18 -0.00969999999998872 -0.4" rpy="0 0 0"/>
      <geometry>
        <mesh filename="neodynium.stl" scale="0.001 0.001 0.001"/>
      </geometry>
    </visual>
    <collision>
      <origin xyz="1.6047283079967634e-18 -0.00969999999998872 -0.4" rpy="0 0 0"/>
      <geometry>
        <mesh filename="neodynium.stl" scale="0.001 0.001 0.001"/>
      </geometry>
    </collision>
    <visual>
      <origin xyz="1.6047283079967634e-18 -0.00969999999998872 -0.4" rpy="0 0 0"/>
      <geometry>
        <mesh filename="wood.stl" scale="0.001 0.001 0.001"/>
      </geometry>
    </visual>
    <collision>
      <origin xyz="1.6047283079967634e-18 -0.00969999999998872 -0.4" rpy="0 0 0"/>
      <geometry>
        <mesh filename="wood.stl" scale="0.001 0.001 0.001"/>
      </geometry>
    </collision>
    <visual>
      <origin xyz="1.6047283079967634e-18 -0.00969999999998872 -0.4" rpy="0 0 0"/>
      <geometry>
        <mesh filename="housing.stl" scale="0.001 0.001 0.001"/>
      </geometry>
    </visual>
    <collision>
      <origin xyz="1.6047283079967634e-18 -0.00969999999998872 -0.4" rpy="0 0 0"/>
      <geometry>
        <mesh filename="housing.stl" scale="0.001 0.001 0.001"/>
      </geometry>
    </collision>
    <visual>
      <origin xyz="1.6047283079967634e-18 -0.00969999999998872 -0.4" rpy="0 0 0"/>
      <geometry>
        <mesh filename="steel.stl" scale="0.001 0.001 0.001"/>
      </geometry>
    </visual>
    <collision>
      <origin xyz="1.6047283079967634e-18 -0.00969999999998872 -0.4" rpy="0 0 0"/>
      <geometry>
        <mesh filename="steel.stl" scale="0.001 0.001 0.001"/>
      </geometry>
    </collision>
    <visual>
      <origin xyz="1.6047283079967634e-18 -0.00969999999998872 -0.4" rpy="0 0 0"/>
      <geometry>
        <mesh filename="aluminum.stl" scale="0.001 0.001 0.001"/>
      </geometry>
    </visual>
    <collision>
      <origin xyz="1.6047283079967634e-18 -0.00969999999998872 -0.4" rpy="0 0 0"/>
      <geometry>
        <mesh filename="aluminum.stl" scale="0.001 0.001 0.001"/>
      </geometry>
    </collision>
  </link>
  <joint name="hinge" type="revolute">
    <parent link="base_link"/>
    <child link="pendulum_link"/>
    <origin xyz="-1.6047283079967634e-18 0.00969999999998872 0.4" rpy="0 0 0"/>
    <axis xyz="0.0 1.0 0.0"/>
    <limit lower="-3.14" upper="3.14" effort="1000" velocity="1000"/>
  </joint>
</robot>
