<?xml version='1.0' encoding='UTF-8'?>
<robot name="pendulum">
  <link name="base_link"/>
  <link name="pendulum_link">
    <inertial>
      <origin xyz="2.971249737646893e-09 0.02576521896158889 0.19294117267885386" rpy="0 0 0"/>
      <mass value="1.4954147111892706"/>
      <inertia ixx="0.002973544185348071" iyy="0.002957665536693213" izz="1.6150801760260592e-05" ixy="-3.3523137095133416e-12" ixz="3.8805288354952e-10" iyz="-0.00020187609191794524"/>
    </inertial>
    <visual>
      <origin xyz="-0.0 -0.0 -0.05" rpy="0 0 0"/>
      <geometry>
        <mesh filename="neodynium.stl" scale="0.001 0.001 0.001"/>
      </geometry>
    </visual>
    <collision>
      <origin xyz="-0.0 -0.0 -0.05" rpy="0 0 0"/>
      <geometry>
        <mesh filename="neodynium.stl" scale="0.001 0.001 0.001"/>
      </geometry>
    </collision>
    <visual>
      <origin xyz="-0.0 -0.0 -0.05" rpy="0 0 0"/>
      <geometry>
        <mesh filename="wood.stl" scale="0.001 0.001 0.001"/>
      </geometry>
    </visual>
    <collision>
      <origin xyz="-0.0 -0.0 -0.05" rpy="0 0 0"/>
      <geometry>
        <mesh filename="wood.stl" scale="0.001 0.001 0.001"/>
      </geometry>
    </collision>
    <visual>
      <origin xyz="-0.0 -0.0 -0.05" rpy="0 0 0"/>
      <geometry>
        <mesh filename="housing.stl" scale="0.001 0.001 0.001"/>
      </geometry>
    </visual>
    <collision>
      <origin xyz="-0.0 -0.0 -0.05" rpy="0 0 0"/>
      <geometry>
        <mesh filename="housing.stl" scale="0.001 0.001 0.001"/>
      </geometry>
    </collision>
    <visual>
      <origin xyz="-0.0 -0.0 -0.05" rpy="0 0 0"/>
      <geometry>
        <mesh filename="steel.stl" scale="0.001 0.001 0.001"/>
      </geometry>
    </visual>
    <collision>
      <origin xyz="-0.0 -0.0 -0.05" rpy="0 0 0"/>
      <geometry>
        <mesh filename="steel.stl" scale="0.001 0.001 0.001"/>
      </geometry>
    </collision>
    <visual>
      <origin xyz="-0.0 -0.0 -0.05" rpy="0 0 0"/>
      <geometry>
        <mesh filename="aluminum.stl" scale="0.001 0.001 0.001"/>
      </geometry>
    </visual>
    <collision>
      <origin xyz="-0.0 -0.0 -0.05" rpy="0 0 0"/>
      <geometry>
        <mesh filename="aluminum.stl" scale="0.001 0.001 0.001"/>
      </geometry>
    </collision>
  </link>
  <joint name="hinge" type="revolute">
    <parent link="base_link"/>
    <child link="pendulum_link"/>
    <origin xyz="0.0 0.0 0.05" rpy="0 0 0"/>
    <axis xyz="0.0 1.0 0.0"/>
    <limit lower="-3.14" upper="3.14" effort="1000" velocity="1000"/>
  </joint>
</robot>
